Workbook

Sheet Cover

Sheet readme
A1: This spreadsheet presents the UK Monetary Policy Event-Study Database (UKMPD) as outlined in Braun, Miranda-Agrippino and Saha.
A2: It captures high-frequency monetary policy surprises and monetary policy factors for the United Kingdom. Both the 'surprises' and 'factors' tab has an 'isMPC' identifier that takes the value TRUE for MPC announcements, and FALSE for press conferences. All datetimes are reported in GMT.
A3: The 'Summary of Asset Prices' tab provides a description of the various asset prices feeding into the dataset.
A4: If using the data, please cite as: Braun, Miranda-Agrippino and Saha, "Measuring Monetary Policy in the UK: the UK Monetary Policy Event-Study Database", Journal of Monetary Economics (2024)
A6: Underlying data source: LSEG (formerly Refinitiv) Tick History and author calculations.
A7: LSEG Tick History link
A9: Notes:
A10: 10 July 2024: The database was revised for publication in the Journal of Monetary Economics. We now include two types of events: MPC announcements (which will capture Inflation Report (IR) / Monetary Policy Report (MPR) announcements in the post-2015 sample) and press conferences (which will capture IR/MPR announcements in the pre-2015 sample).
A11: 8 February 2024: We have revised the dataset to remove 3 observations in 2020, for the May, August and November MPC announcements and MPR publications which occured at 7am local time. These had previously been recorded as a 12pm local time publication. As 7am falls outside of UK financial market trading hours, data is not available at that time. There are also underlying data availability issues for MPC events on 9th July 1998, 8th March 2001, 10th April 2003 and 11th March 2020, which result in missing observations on those dates. The dataset is currently being revised for publication and may evolve.
A13: Disclaimers
A14: All material included herein is intended for general informational purposes only. No user should act or refrain from acting on this information without first verifying the information and obtaining professional advice.
A15: The Bank of England does not accept any responsibility or liability for loss or damage, whether direct, indirect or consequential, resulting from the use of, or the inability to use, this information whether as a result of inaccuracies, defects, errors (typographical or otherwise), omissions, out of date information or otherwise, or from any reliance on information contained herein.
... A18: Any dispute arising out of use of this information database or the Terms and Conditions found on the Bank of England’s website shall be governed by the laws of England and the user and the Bank submit to the exclusive jurisdiction of the English courts. The Bank’s omission to exercise any right under these Terms and Conditions shall not constitute a waiver of such right.

Sheet summary of asset prices
A2: # RIC | B2: Description | C2: Availability | D2: Transformation
A3: Interest Rate Futures
A4: FSScm1 | B4: 3M Libor 1st quarterly contract | C4: 1997 - 2021 | D4: Yield (pp)
A5: FSScm2 | B5: 3M Libor 2nd quarterly contract | C5: 1997 - 2021 | D5: Yield (pp)
A6: FSScm3 | B6: 3M Libor 3rd quarterly contract | C6: 1997 - 2021 | D6: Yield (pp)
A7: FSScm4 | B7: 3M Libor 4th quarterly contract | C7: 1997 - 2021 | D7: Yield (pp)
A8: Son3c1 | B8: 3M Sonia 1st quarterly contract | C8: Since 2021 | D8: Yield (pp)
A9: Son3c2 | B9: 3M Sonia 2nd quarterly contract | C9: Since 2021 | D9: Yield (pp)
A10: Son3c3 | B10: 3M Sonia 3rd quarterly contract | C10: Since 2021 | D10: Yield (pp)
A11: Son3c4 | B11: 3M Sonia 4th quarterly contract | C11: Since 2021 | D11: Yield (pp)
A12: Gilt Yields
A13: GBP1YT=RR | B13: 1 Year Reference Bond | C13: Since 1997 | D13: Yield (pp)
A14: GBP2YT=RR | B14: 2 Year Reference Bond | C14: Since 1997 | D14: Yield (pp)
A15: GBP5YT=RR | B15: 5 Year Reference Bond | C15: Since 1997 | D15: Yield (pp)
A16: GBP10YT=RR | B16: 10 Year Reference Bond | C16: Since 1997 | D16: Yield (pp)
A17: Overnight Indexed Swaps
A18: GBP1MOIS=RR | B18: 1 Month OIS rate | C18: Since 2009 | D18: Yield (pp)
A19: GBP2MOIS=RR | B19: 2 Month OIS rate | C19: Since 2009 | D19: Yield (pp)
A20: GBP3MOIS=RR | B20: 3 Month OIS rate | C20: Since 2009 | D20: Yield (pp)
A21: GBP1YOIS=RR | B21: 1 Year OIS rate | C21: Since 2009 | D21: Yield (pp)
A22: GBP2YOIS=RR | B22: 2 Year OIS rate | C22: Since 2009 | D22: Yield (pp)
A23: GBP3YOIS=RR | B23: 3 Year OIS rate | C23: Since 2015 | D23: Yield (pp)
A24: Exchange Rates and Stock Market Indexes
A25: FFIc1 | B25: FTSE100 future first month contract | C25: Since 1997 | D25: 100 × ln
A26: .FTSE | B26: FTSE 100 Index | C26: Since 1997 | D26: 100 × ln
A27: .FTMC | B27: FTSE 250 Index | C27: Since 1997 | D27: 100 × ln
A28: .FTAS | B28: FTSE All Share Index | C28: Since 1997 | D28: 100 × ln
A29: EURGBP= | B29: EUR/GBP exchange rate | C29: Since 1998 | D29: 100 × ln
A30: GBP= | B30: GBP/USD exchange rate | C30: Since 1997 | D30: 100 × ln

Sheet surprises
A1: Datetime | B1: isMPC | C1: FSScm1 | D1: FSScm2 | E1: FSScm3 | F1: FSScm4 | G1: GB10YT=RR | H1: GB1YT=RR | I1: GB2YT=RR | J1: GB5YT=RR | K1: GBP1MOIS= | L1: GBP1YOIS= | M1: GBP2MOIS= | N1: GBP2YOIS= | O1: GBP3MOIS= | P1: GBP3YOIS= | Q1: FFIc1 | R1: EURGBP= | S1: GBP= | T1: .FTAS | U1: .FTMC | V1: .FTSE | W1: SON3c1 | X1: SON3c2 | Y1: SON3c3 | Z1: SON3c4
A2: 35587.458 | B2: TRUE | C2: 0.07 | D2: 0.02 | E2: 0.02 | F2: 0.025 | G2: 0.021 | H2: 0 | I2: 0 | J2: 0 | Q2: -0.16259285 | S2: -0.0030734713 | T2: 0.024180763 | U2: -0.011185307 | V2: 0.036914392
A3: 35621.458 | B3: TRUE | C3: 0.01 | D3: 0.01 | E3: 0.01 | F3: 0.005 | G3: 0 | H3: -0.0555 | I3: 0.046 | J3: 0.008 | Q3: 0.29371677 | S3: 0.11247929 | T3: 0.14212604 | U3: 0.015957144 | V3: 0.18532564
A4: 35649.458 | B4: TRUE | C4: -0.07 | D4: -0.11 | E4: -0.1 | F4: -0.11 | G4: -0.0805 | H4: -0.05 | I4: -0.0815 | J4: -0.0695 | Q4: 1.185082 | S4: -0.40337135 | T4: 0.51155368 | U4: 0.079384335 | V4: 0.64906293
A5: 35655.396 | B5: FALSE | C5: -0.02 | D5: -0.02 | E5: -0.02 | F5: -0.02 | G5: -0.0085 | H5: -0.013 | I5: -0.0175 | J5: -0.0245 | Q5: 0.059400061 | S5: -0.42403785 | T5: 0.028847051 | U5: -0.072626298 | V5: 0.051729971
A6: 35684.458 | B6: TRUE | C6: 0 | D6: 0.02 | E6: 0.015 | F6: 0.01 | G6: 0 | H6: -0.015 | I6: 0.0045 | J6: -0.0025 | Q6: -0.010270631 | S6: 0.028313907 | T6: 0.07175364 | U6: -0.025876569 | V6: 0.10067908
A7: 35712.458 | B7: TRUE | C7: 0.03 | D7: 0.04 | E7: 0.03 | F7: 0.04 | G7: -0.004 | H7: -0.0175 | I7: -0.0045 | J7: -0.0075 | Q7: 0.12224366 | S7: -0.070914335 | T7: 0.097372571 | U7: 0.012298862 | V7: 0.12378714
A8: 35740.5 | B8: TRUE | C8: 0.15 | D8: 0.15 | E8: 0.12 | F8: 0.085 | G8: 0.0125 | H8: 0.061 | I8: 0.0075 | J8: 0.016 | Q8: -0.54928426 | S8: 0.5238419 | T8: -0.44517128 | U8: -0.040557127 | V8: -0.57723172
A9: 35746.438 | B9: FALSE | C9: -0.04 | D9: -0.07 | E9: -0.08 | F9: -0.06 | G9: -0.0335 | H9: -0.021 | I9: -0.024 | J9: -0.0405 | Q9: 0.010594904 | S9: 0.020474721 | T9: -0.081349876 | U9: -0.31079212 | V9: -0.010646793
A10: 35768.5 | B10: TRUE | C10: -0.03 | D10: -0.05 | E10: -0.04 | F10: -0.035 | G10: -0.0125 | H10: -0.0165 | I10: -0.025 | J10: -0.018 | Q10: 0.15746485 | S10: -0.14604852 | T10: 0.11537864 | U10: 0.061486925 | V10: 0.13448571
A11: 35803.5 | B11: TRUE | C11: -0.03 | D11: -0.035 | E11: -0.04 | F11: -0.035 | G11: -0.012 | H11: -0.018 | I11: -0.021 | J11: -0.0145 | Q11: 0.028220686 | S11: -0.39455079 | T11: 0.0036436141 | U11: 0.059445112 | V11: -0.0094827178
A12: 35831.5 | B12: TRUE | C12: -0.02 | D12: -0.02 | E12: -0.01 | F12: -0.02 | G12: -0.003 | H12: -0.0305 | I12: -0.022 | J12: -0.0165 | Q12: -0.061622433 | S12: -0.090713925 | T12: -0.026712358 | U12: 0.02824061 | V12: -0.045899093
A13: 35837.438 | B13: FALSE | C13: 0.06 | D13: 0.05 | E13: 0.04 | F13: 0.02 | G13: 0.019 | H13: 0.041 | I13: 0.039 | J13: 0.037 | Q13: 0.24855761 | S13: 0.38125738 | T13: 0.15512638 | U13: 0.042048356 | V13: 0.19204786
... A17: 35928.396 | B17: FALSE | C17: -0.01 | D17: -0.01 | E17: -0.01 | F17: -0.005 | G17: -0.005 | H17: 0.0265 | I17: -0.006 | J17: -0.015 | Q17: -0.1665002 | S17: 0.015281874 | T17: -0.14721966 | U17: 0 | V17: -0.18598422
A18: 35950.458 | B18: TRUE | C18: 0.19 | D18: 0.22 | E18: 0.19 | F18: 0.19 | G18: 0.042 | H18: 0.077 | I18: 0.067 | J18: 0.0195 | Q18: -0.56122596 | R18: -0.55254865 | S18: 0.51179055 | T18: -0.4523103 | U18: -0.15178348 | V18: -0.55041164
A19: 36013.458 | B19: TRUE | C19: -0.09 | D19: -0.07 | E19: -0.07 | F19: -0.07 | G19: -0.018 | H19: -0.064 | I19: -0.0755 | J19: -0.058 | Q19: 0.017830079 | R19: 0.0073354117 | S19: -0.036733195 | T19: -0.033867154 | U19: 0.0018765071 | V19: -0.042951483
A20: 36020.396 | B20: FALSE | C20: 0.03 | D20: 0.05 | E20: 0.06 | F20: 0.065 | G20: 0.014 | H20: 0.0415 | I20: 0.01 | J20: 0.024 | Q20: 0.11130694 | R20: 0.2429777 | S20: 0.030759766 | T20: 0.054539635 | U20: -0.20351408 | V20: 0.15829123
A21: 36048.458 | B21: TRUE | C21: 0.055 | D21: -0.06 | E21: -0.07 | F21: -0.05 | G21: -0.0235 | H21: -0.072 | I21: -0.0515 | J21: -0.025 | Q21: -1.0848983 | R21: 0.094131284 | S21: 0.071826184 | T21: -0.78656899 | U21: -0.099748559 | V21: -0.99055976
A22: 36076.458 | B22: TRUE | C22: -0.09 | D22: -0.07 | E22: -0.055 | F22: -0.03 | G22: 0.009 | H22: -0.029 | I22: -0.06 | J22: -0.03 | Q22: -0.35785745 | R22: -0.28634304 | S22: 0.33968706 | T22: -0.34373182 | U22: -0.23027818 | V22: -0.33169642
A23: 36104.5 | B23: TRUE | C23: -0.1 | D23: -0.06 | E23: -0.05 | F23: -0.04 | G23: -0.024 | H23: -0.136 | I23: -0.114 | J23: -0.071 | Q23: -0.035842294 | R23: 0.33658261 | S23: -0.30501179 | T23: -0.12086579 | U23: 0.093040196 | V23: -0.16602606
A24: 36110.438 | B24: FALSE | C24: 0.13 | D24: 0.14 | E24: 0.125 | F24: 0.115 | G24: 0.079 | H24: 0.139 | I24: 0.135 | J24: 0.114 | Q24: 0.27164088 | R24: -0.4753299 | S24: 0.33765483 | T24: 0.13233289 | U24: 0.1556835 | V24: 0.13669545
A25: 36139.5 | B25: TRUE | C25: -0.05 | D25: -0.08 | E25: -0.06 | F25: -0.05 | G25: -0.012 | H25: -0.062 | I25: -0.031 | J25: -0.011 | Q25: 0.10507882 | R25: -0.16200039 | S25: 0.21646332 | T25: 0.050782123 | U25: 0.035525093 | V25: 0.057862762
A26: 36167.5 | B26: TRUE | C26: -0.07 | D26: -0.07 | E26: -0.09 | F26: -0.08 | G26: 0.001 | H26: -0.017 | I26: -0.006 | J26: -0.003 | Q26: 0.064966707 | R26: 0.084931706 | S26: -0.16958395 | T26: 0.13560498 | U26: 0.028284543 | V26: 0.1339388
A27: 36195.5 | B27: TRUE | C27: -0.17 | D27: -0.085 | E27: -0.06 | F27: -0.04 | G27: -0.045 | H27: -0.139 | I27: -0.078 | J27: -0.072 | Q27: 0.32428416 | R27: 0.20320785 | S27: -0.19263999 | T27: 0.36756027 | U27: 0.27868464 | V27: 0.40721744
A28: 36201.438 | B28: FALSE | C28: -0.07 | D28: -0.06 | E28: -0.07 | F28: -0.06 | G28: 0 | H28: 0 | I28: 0 | J28: 0 | Q28: -0.13072467 | R28: 0.28835083 | S28: -0.17768524 | T28: -0.086991402 | U28: -0.050404204 | V28: -0.092277431
A29: 36222.5 | B29: TRUE | C29: 0.14 | D29: 0.1 | E29: 0.1 | F29: 0.07 | G29: 0.044 | H29: 0.128 | I29: 0.109 | J29: 0.079 | Q29: -0.60780475 | R29: -0.31850699 | S29: 0.23503227 | T29: -0.45793993 | U29: 0.024567007 | V29: -0.62753808
... A57: 36867.5 | B57: TRUE | C57: 0 | D57: 0 | E57: -0.005 | F57: 0 | G57: -0.0025 | H57: 0.0055 | I57: -0.0065 | J57: -0.006 | Q57: -0.2927203 | R57: 0.26689328 | S57: -0.23495277 | T57: -0.21111335 | U57: -0.095430135 | V57: -0.23140347
A58: 36902.5 | B58: TRUE | C58: 0.04 | D58: 0.025 | E58: 0.02 | F58: 0.005 | Q58: -0.17994443 | R58: 0.015724507 | S58: 0.21383236 | T58: -0.10270988 | U58: 0.0061064041 | V58: -0.12481731
A59: 36930.5 | B59: TRUE | C59: 0.02 | D59: 0.01 | E59: 0.02 | F59: 0.01 | G59: 0.0145 | H59: 0.007 | I59: 0.012 | J59: 0.0135 | Q59: -0.048125126 | R59: -0.13367409 | S59: 0.10685051 | T59: -0.018967913 | U59: 0.086957168 | V59: -0.046556804
A60: 36936.438 | B60: FALSE | C60: 0.02 | D60: 0.02 | E60: 0.02 | F60: 0.02 | G60: 0.016 | H60: 0.0145 | I60: 0.008 | J60: 0.012 | Q60: 0.068930565 | R60: -0.21378527 | S60: 0.099504203 | T60: 0.15648299 | U60: 0.13041483 | V60: 0.16534824
A61: 36986.458 | B61: TRUE | C61: 0 | D61: 0 | E61: 0 | F61: 0 | G61: 0.007 | H61: 0 | I61: 0 | J61: 0.0125 | Q61: -0.11530957 | R61: 0.10364761 | S61: 0.11133921 | T61: -0.083557241 | U61: 0.023237286 | V61: -0.10351229
A62: 37021.458 | B62: TRUE | C62: 0.05 | D62: 0.05 | E62: 0.03 | F62: 0.03 | G62: 0.005 | H62: 0.038 | I62: 0.0195 | J62: 0.005 | Q62: 0.25177303 | R62: -0.0080266485 | S62: 0.045645267 | T62: 0.20094749 | U62: 0.013857986 | V62: 0.24771467
A63: 37027.396 | B63: FALSE | C63: 0 | D63: -0.01 | E63: 0 | F63: -0.005 | G63: -0.0095 | H63: 0.0045 | I63: 0.005 | J63: -0.008 | Q63: -0.038723835 | R63: -0.10508873 | S63: 0.014011489 | T63: -0.10702552 | U63: -0.071281363 | V63: -0.1104572
A64: 37048.458 | B64: TRUE | C64: 0.01 | D64: -0.01 | E64: -0.015 | F64: -0.01 | G64: 0.0015 | H64: 0 | I64: -0.005 | J64: -0.001 | Q64: 0 | R64: 0.20516194 | S64: -0.010700337 | T64: 0.073623385 | U64: -0.043488368 | V64: 0.082363328
A65: 37077.458 | B65: TRUE | C65: 0 | D65: -0.01 | E65: -0.01 | F65: -0.01 | G65: -0.0025 | H65: 0 | I65: -0.005 | J65: -0.002 | Q65: 0.085349151 | R65: 0.058423404 | S65: -0.053377935 | T65: 0.083602371 | U65: -0.18697921 | V65: 0.13176303
A66: 37105.458 | B66: TRUE | C66: -0.17 | D66: -0.25 | E66: -0.24 | F66: -0.22 | G66: -0.02 | H66: -0.1805 | I66: -0.108 | J66: -0.061 | Q66: 0.5037794 | R66: 0.10558377 | S66: -0.073256243 | T66: 0.49681253 | U66: 0.30258678 | V66: 0.53976896
A67: 37111.396 | B67: FALSE | C67: 0.01 | D67: 0.01 | E67: 0.02 | F67: 0.02 | G67: 0.0015 | H67: 0.012 | I67: 0.005 | J67: 0.0025 | Q67: -0.53609604 | R67: -0.064756356 | S67: 0.031764519 | T67: -0.4666966 | U67: -0.27071119 | V67: -0.51742285
A68: 37140.458 | B68: TRUE | C68: 0.02 | D68: 0 | E68: -0.01 | F68: -0.01 | G68: 0.0035 | H68: -8.8817842e-16 | I68: -0.006 | J68: 0 | Q68: 0.043054991 | R68: -0.016378675 | S68: -0.19290395 | T68: 0.071140624 | U68: -0.038528222 | V68: 0.08617636
A69: 37152.458 | B69: TRUE | C69: 0.04 | D69: 0.02 | E69: 0 | F69: 0 | G69: -0.0145 | H69: -0.014 | I69: 0.003 | J69: -0.0065 | Q69: 0.094043894 | R69: 0.095260784 | S69: 0.017038388 | T69: 0.021694327 | U69: -0.30273812 | V69: 0.066899423
A70: 37168.458 | B70: TRUE | C70: -0.06 | D70: -0.02 | E70: 0 | F70: -0.01 | G70: -0.0165 | H70: -0.03 | I70: -0.021 | J70: -0.0175 | Q70: -0.43470726 | R70: -0.16904814 | S70: 0.037349541 | T70: -0.33312983 | U70: 0.17201562 | V70: -0.42042648
...

Sheet factors
A1: Datetime | B1: isMPC | C1: Target | D1: Path | E1: QE
A2: 35587.458 | B2: TRUE | C2: 0.057369308 | D2: -0.033270229 | E2: -0.0058653674
A3: 35621.458 | B3: TRUE | C3: 0.012228002 | D3: -0.0065044754 | E3: 0.011546039
A4: 35649.458 | B4: TRUE | C4: -0.072559781 | D4: -0.017190075 | E4: -0.042270315
A5: 35655.396 | B5: FALSE | C5: -0.019555864 | D5: 0.0032392097 | E5: -0.0094830002
A6: 35684.458 | B6: TRUE | C6: 0.0041172975 | D6: 0.015697594 | E6: -0.0057347723
A7: 35712.458 | B7: TRUE | C7: 0.027446481 | D7: 0.025569043 | E7: -0.022338065
A8: 35740.5 | B8: TRUE | C8: 0.15013052 | D8: 0.0012446054 | E8: -0.049143305
A9: 35746.438 | B9: FALSE | C9: -0.043131537 | D9: -0.026451079 | E9: -0.0086805695
A10: 35768.5 | B10: TRUE | C10: -0.033804177 | D10: -0.010732889 | E10: -0.00088158017
A11: 35803.5 | B11: TRUE | C11: -0.028697618 | D11: -0.011305865 | E11: -0.00093960677
A12: 35831.5 | B12: TRUE | C12: -0.019565483 | D12: 0.0042175407 | E12: -0.0061284236
A13: 35837.438 | B13: FALSE | C13: 0.062643461 | D13: -0.031990179 | E13: 0.012590726
... A416: 45967.521 | B416: FALSE | C416: 0.00059086983 | D416: 0.019042422 | E416: -0.012916662
A417: mean | C417: =AVERAGE(C2:C416) -> -0.002218728 | D417: =AVERAGE(D2:D416) -> -0.0045020229 | E417: =AVERAGE(E2:E416) -> -0.0021627293
A418: std.dev. | C418: =_xlfn.STDEV.P(C2:C417) -> 0.0467833 | D418: =_xlfn.STDEV.P(D2:D417) -> 0.032429104 | E418: =_xlfn.STDEV.P(E2:E417) -> 0.028744819
A419: corr(T,P) | C419: =CORREL(C2:C416,D2:D416) -> -0.0065681145 | D419: =CORREL(C2:C416,D2:D416) -> -0.0065681145
A420: corr(T,QE) | C420: =CORREL(C2:C416,E2:E416) -> -0.0035596767 | E420: =CORREL(C2:C416,E2:E416) -> -0.0035596767
A421: corr(P,QE) | D421: =CORREL(D2:D416,E2:E416) -> -0.010420057 | E421: =CORREL(D2:D416,E2:E416) -> -0.010420057

Sheet Literature Review
A1: Paper | B1: Topic | C1: Main Result | D1: Method | E1: Useful for
A2: Antulio N. Bomfim
